<?xml version="1.0" ?>
<!-- =================================================================================== -->
<!-- |    This document was autogenerated by xacro from robot_description.xacro        | -->
<!-- |    EDITING THIS FILE BY HAND IS NOT RECOMMENDED                                 | -->
<!-- =================================================================================== -->
<robot>
  <link name="chassis_link">
    <visual>
      <origin rpy="0.0 0.0 0.0" xyz="0.0 0.0 -0.12"/>
      <geometry>
        <box size="0.7 0.42 0.2"/>
      </geometry>
      <material name="">
        <color rgba="0.0 0.0 0.0 1.0"/>
      </material>
    </visual>
    <collision>
      <origin rpy="0.0 0.0 0.0" xyz="0.0 0.0 -0.12"/>
      <geometry>
        <box size="0.7 0.42 0.2"/>
      </geometry>
    </collision>
    <inertial>
      <origin xyz="-0.0037041613 0.0428197174 -0.1106721127"/>
      <mass value="27.0"/>
      <inertia ixx="0.6797017835" ixy="-0.0079907052" ixz="0.0127828566" iyy="1.2877765418" iyz="0.0117679376" izz="1.6878998816"/>
    </inertial>
  </link>
  <link name="shaft_left_link">
    <visual>
      <origin rpy="-1.5707963267948966 -1.5707963267948966 0.0" xyz="-0.1 0.0 -0.231"/>
      <geometry>
        <mesh filename="package://morpheus_description/urdf/01_robot_description/meshes/stl/shaft.stl"/>
      </geometry>
    </visual>
    <collision>
      <origin rpy="-1.571 -1.5707999999991324 0.0" xyz="-0.1 0.0 -0.231014"/>
      <geometry>
        <mesh filename="package://morpheus_description/urdf/01_robot_description/meshes/stl/shaft.stl"/>
      </geometry>
    </collision>
    <inertial>
      <origin xyz="-0.0002091194 1.32101e-05 0.0184469812"/>
      <mass value="0.75"/>
      <inertia ixx="0.0012178097" ixy="-5.6e-09" ixz="2.83456e-05" iyy="0.0008777415" iyz="1.4e-09" izz="0.0004882588"/>
    </inertial>
  </link>
  <joint name="shaft_left_joint" type="revolute">
    <origin rpy="1.5707999999991324 -1.5707900000007928 -3.1415899999999253" xyz="0.0 0.235014 -0.113"/>
    <parent link="chassis_link"/>
    <child link="shaft_left_link"/>
    <axis xyz="0.0 0.0 1.0"/>
    <limit effort="10.0" lower="-3.141592653589793" upper="3.141592653589793" velocity="10.0"/>
    <dynamics damping="0.7" friction="0.0"/>
  </joint>
  <link name="strut_fl_link">
    <visual>
      <origin rpy="-1.5707963267948966 -1.5707963267948966 0.0" xyz="-0.095 -0.03 -0.321"/>
      <geometry>
        <mesh filename="package://morpheus_description/urdf/01_robot_description/meshes/dae/strut.dae"/>
      </geometry>
    </visual>
    <collision>
      <origin rpy="-1.571 -1.5707999999991324 0.0" xyz="-0.0947906 -0.0295442 -0.320703"/>
      <geometry>
        <mesh filename="package://morpheus_description/urdf/01_robot_description/meshes/stl/strut.stl"/>
      </geometry>
    </collision>
    <inertial>
      <origin xyz="-0.0739820888 0.4431306277 -0.0142543342"/>
      <mass value="0.6"/>
      <inertia ixx="0.0120960241" ixy="0.0019557104" ixz="-1.01651e-05" iyy="0.0007162043" iyz="5.93325e-05" izz="0.0122581859"/>
    </inertial>
  </link>
  <joint name="strut_fl_joint" type="fixed">
    <origin rpy="0.0 0.0 0.0" xyz="-0.00520945 0.0295442 0.0899929"/>
    <parent link="shaft_left_link"/>
    <child link="strut_fl_link"/>
  </joint>
  <link name="steering_fl_link">
    <visual>
      <origin rpy="1.5707963267948966 0.0012042771838760874 0.0" xyz="-0.308 0.536 0.017"/>
      <geometry>
        <mesh filename="package://morpheus_description/urdf/01_robot_description/meshes/dae/steering.dae"/>
      </geometry>
    </visual>
    <collision>
      <origin rpy="1.571 0.0012006700002099185 0.0" xyz="-0.308035 0.536061 0.0167576"/>
      <geometry>
        <mesh filename="package://morpheus_description/urdf/01_robot_description/meshes/stl/steering.stl"/>
      </geometry>
    </collision>
    <inertial>
      <origin xyz="0.0004367622 0.0434819885 -0.1159842788"/>
      <mass value="1.6"/>
      <inertia ixx="0.0052279077" ixy="1.8091e-06" ixz="1.3286e-05" iyy="0.0053004683" iyz="0.0005027067" izz="0.0014735517"/>
    </inertial>
  </link>
  <joint name="steering_fl_joint" type="revolute">
    <origin rpy="-1.5695999999994064 -0.0015880299992990737 -1.5707999999991324" xyz="-0.111216 0.504597 -0.0155261"/>
    <parent link="strut_fl_link"/>
    <child link="steering_fl_link"/>
    <axis xyz="0.0 0.0 1.0"/>
    <limit effort="10.0" lower="-3.141592653589793" upper="3.141592653589793" velocity="10.0"/>
    <dynamics damping="0.7" friction="0.0"/>
  </joint>
  <link name="wheel_fl_link">
    <visual>
      <origin rpy="0.0 0.0 0.0" xyz="0.0 0.0 -0.04"/>
      <geometry>
        <mesh filename="package://morpheus_description/urdf/01_robot_description/meshes/dae/wheel.dae"/>
      </geometry>
    </visual>
    <collision>
      <origin rpy="0.0 0.0 0.0" xyz="0.0 0.0 -0.04"/>
      <geometry>
        <mesh filename="package://morpheus_description/urdf/01_robot_description/meshes/stl/wheel.stl"/>
      </geometry>
    </collision>
    <inertial>
      <origin xyz="0.0 -0.0002387564 -0.04"/>
      <mass value="1.4"/>
      <inertia ixx="0.0062960167" ixy="0.0" ixz="-1.7e-09" iyy="0.0062960234" iyz="0.0" izz="0.0111555186"/>
    </inertial>
  </link>
  <joint name="wheel_fl_joint" type="continuous">
    <origin rpy="1.5707999999991324 0.002023000000786 -0.026182653588951874" xyz="0.000859913 -0.0328387 -0.152"/>
    <parent link="steering_fl_link"/>
    <child link="wheel_fl_link"/>
    <axis xyz="0.0 0.0 1.0"/>
    <limit effort="10.0" lower="0.0" upper="0.0" velocity="10.0"/>
    <dynamics damping="0.0" friction="0.0"/>
  </joint>
  <link name="strut_rl_link">
    <visual>
      <origin rpy="-1.5707963267948966 -1.5707963267948966 0.0" xyz="-0.095 -0.03 -0.295"/>
      <geometry>
        <mesh filename="package://morpheus_description/urdf/01_robot_description/meshes/dae/strut.dae"/>
      </geometry>
    </visual>
    <collision>
      <origin rpy="-1.571 -1.5707999999991324 0.0" xyz="-0.0947906 -0.0295442 -0.295326"/>
      <geometry>
        <mesh filename="package://morpheus_description/urdf/01_robot_description/meshes/stl/strut.stl"/>
      </geometry>
    </collision>
    <inertial>
      <origin xyz="-0.0756316965 0.4736684486 0.0110207527"/>
      <mass value="0.6"/>
      <inertia ixx="0.0120903014" ixy="0.0019549161" ixz="-1.01621e-05" iyy="0.000716067" iyz="5.92839e-05" izz="0.0122522986"/>
    </inertial>
  </link>
  <joint name="strut_rl_joint" type="fixed">
    <origin rpy="3.1415899999999253 0.0 0.0" xyz="-0.00520945 -0.0295443 0.0899929"/>
    <parent link="shaft_left_link"/>
    <child link="strut_rl_link"/>
  </joint>
  <link name="steering_rl_link">
    <visual>
      <origin rpy="1.5707963267948966 0.0012042771838760874 0.0" xyz="-0.308 0.536 0.017"/>
      <geometry>
        <mesh filename="package://morpheus_description/urdf/01_robot_description/meshes/dae/steering.dae"/>
      </geometry>
    </visual>
    <collision>
      <origin rpy="1.571 0.0012006700002099185 0.0" xyz="-0.308035 0.536061 0.0167576"/>
      <geometry>
        <mesh filename="package://morpheus_description/urdf/01_robot_description/meshes/stl/steering.stl"/>
      </geometry>
    </collision>
    <inertial>
      <origin xyz="0.0004367622 0.0434819885 -0.1159842788"/>
      <mass value="1.6"/>
      <inertia ixx="0.0052279077" ixy="1.8091e-06" ixz="1.3286e-05" iyy="0.0053004683" iyz="0.0005027067" izz="0.0014735517"/>
    </inertial>
  </link>
  <joint name="steering_rl_joint" type="revolute">
    <origin rpy="1.5695999999994064 0.0015880299992990737 1.5707900000007928" xyz="-0.111216 0.504597 0.00985065"/>
    <parent link="strut_rl_link"/>
    <child link="steering_rl_link"/>
    <axis xyz="0.0 0.0 1.0"/>
    <limit effort="10.0" lower="-3.141592653589793" upper="3.141592653589793" velocity="10.0"/>
    <dynamics damping="0.7" friction="0.0"/>
  </joint>
  <link name="wheel_rl_link">
    <visual>
      <origin rpy="0.0 0.0 0.0" xyz="0.0 0.0 0.04"/>
      <geometry>
        <mesh filename="package://morpheus_description/urdf/01_robot_description/meshes/dae/wheel.dae"/>
      </geometry>
    </visual>
    <collision>
      <origin rpy="0.0 0.0 0.0" xyz="0.0 0.0 0.04"/>
      <geometry>
        <mesh filename="package://morpheus_description/urdf/01_robot_description/meshes/stl/wheel.stl"/>
      </geometry>
    </collision>
    <inertial>
      <origin xyz="0.0 -0.0002387564 0.04"/>
      <mass value="1.4"/>
      <inertia ixx="0.0062960167" ixy="0.0" ixz="-1.7e-09" iyy="0.0062960234" iyz="0.0" izz="0.0111555186"/>
    </inertial>
  </link>
  <joint name="wheel_rl_joint" type="continuous">
    <origin rpy="-1.5707999999991324 0.0020191899993887734 3.1154100000008413" xyz="0.000859913 0.0328387 -0.152"/>
    <parent link="steering_rl_link"/>
    <child link="wheel_rl_link"/>
    <axis xyz="0.0 0.0 1.0"/>
    <limit effort="10.0" lower="0.0" upper="0.0" velocity="10.0"/>
    <dynamics damping="0.0" friction="0.0"/>
  </joint>
  <link name="shaft_right_link">
    <visual>
      <origin rpy="-3.141592653589793 1.5707963267948966 0.0" xyz="0.0 0.1 0.231"/>
      <geometry>
        <mesh filename="package://morpheus_description/urdf/01_robot_description/meshes/stl/shaft.stl"/>
      </geometry>
    </visual>
    <collision>
      <origin rpy="-3.142 1.5707999999991324 0.0" xyz="0.0 0.1 0.231014"/>
      <geometry>
        <mesh filename="package://morpheus_description/urdf/01_robot_description/meshes/stl/shaft.stl"/>
      </geometry>
    </collision>
    <inertial>
      <origin xyz="-1.32101e-05 0.0002091194 -0.0184469812"/>
      <mass value="0.75"/>
      <inertia ixx="0.0" ixy="0.0" ixz="0.0" iyy="0.0" iyz="0.0" izz="0.0"/>
    </inertial>
  </link>
  <joint name="shaft_right_joint" type="revolute">
    <origin rpy="-1.5707999999991324 0.0 0.0" xyz="8.1925e-05 -0.231256 -0.115299"/>
    <parent link="chassis_link"/>
    <child link="shaft_right_link"/>
    <axis xyz="0.0 0.0 1.0"/>
    <limit effort="10.0" lower="-3.141592653589793" upper="3.141592653589793" velocity="10.0"/>
    <dynamics damping="0.7" friction="0.0"/>
    <mimic joint="shaft_left_joint" multiplier="-1.0" offset="0.0"/>
  </joint>
  <link name="strut_fr_link">
    <visual>
      <origin rpy="-1.5707963267948966 -1.5707963267948966 0.0" xyz="-0.095 -0.03 -0.295"/>
      <geometry>
        <mesh filename="package://morpheus_description/urdf/01_robot_description/meshes/dae/strut.dae"/>
      </geometry>
    </visual>
    <collision>
      <origin rpy="-1.571 -1.5707999999991324 0.0" xyz="-0.0947906 -0.0295442 -0.295326"/>
      <geometry>
        <mesh filename="package://morpheus_description/urdf/01_robot_description/meshes/stl/strut.stl"/>
      </geometry>
    </collision>
    <inertial>
      <origin xyz="-0.0739820888 0.4431306277 0.0117456658"/>
      <mass value="0.6"/>
      <inertia ixx="0.0120960241" ixy="0.0019557104" ixz="-1.01651e-05" iyy="0.0007162043" iyz="5.93325e-05" izz="0.0122581859"/>
    </inertial>
  </link>
  <joint name="strut_fr_joint" type="fixed">
    <origin rpy="0.0 0.0 -1.5707999999991324" xyz="0.0295443 0.00520945 -0.0899929"/>
    <parent link="shaft_right_link"/>
    <child link="strut_fr_link"/>
  </joint>
  <link name="steering_fr_link">
    <visual>
      <origin rpy="1.5707963267948966 0.0012042771838760874 0.0" xyz="-0.308 0.536 0.017"/>
      <geometry>
        <mesh filename="package://morpheus_description/urdf/01_robot_description/meshes/dae/steering.dae"/>
      </geometry>
    </visual>
    <collision>
      <origin rpy="1.571 0.0012006700002099185 0.0" xyz="-0.308035 0.536061 0.0167576"/>
      <geometry>
        <mesh filename="package://morpheus_description/urdf/01_robot_description/meshes/stl/steering.stl"/>
      </geometry>
    </collision>
    <inertial>
      <origin xyz="0.0004367622 0.0434819885 -0.1159842788"/>
      <mass value="1.6"/>
      <inertia ixx="0.0052279077" ixy="1.8091e-06" ixz="1.3286e-05" iyy="0.0053004683" iyz="0.0005027067" izz="0.0014735517"/>
    </inertial>
  </link>
  <joint name="steering_fr_joint" type="revolute">
    <origin rpy="-1.5695899999993215 3.141592653589793 -1.5707600000005377" xyz="-0.111216 0.504597 0.00985065"/>
    <parent link="strut_fr_link"/>
    <child link="steering_fr_link"/>
    <axis xyz="0.0 0.0 1.0"/>
    <limit effort="10.0" lower="-3.141592653589793" upper="3.141592653589793" velocity="10.0"/>
    <dynamics damping="0.7" friction="0.0"/>
  </joint>
  <link name="wheel_fr_link">
    <visual>
      <origin rpy="0.0 0.0 0.0" xyz="0.0 0.0 -0.04"/>
      <geometry>
        <mesh filename="package://morpheus_description/urdf/01_robot_description/meshes/dae/wheel.dae"/>
      </geometry>
    </visual>
    <collision>
      <origin rpy="0.0 0.0 0.0" xyz="0.0 0.0 -0.04"/>
      <geometry>
        <mesh filename="package://morpheus_description/urdf/01_robot_description/meshes/stl/wheel.stl"/>
      </geometry>
    </collision>
    <inertial>
      <origin xyz="0.0 -0.0002387564 -0.04"/>
      <mass value="1.4"/>
      <inertia ixx="0.0062960167" ixy="0.0" ixz="-1.7e-09" iyy="0.0062960234" iyz="0.0" izz="0.0111555186"/>
    </inertial>
  </link>
  <joint name="wheel_fr_joint" type="continuous">
    <origin rpy="-1.5707999999991324 0.00442516999951294 -0.026179900000444293" xyz="0.000859913 0.0328387 -0.152"/>
    <parent link="steering_fr_link"/>
    <child link="wheel_fr_link"/>
    <axis xyz="0.0 0.0 1.0"/>
    <limit effort="10.0" lower="0.0" upper="0.0" velocity="10.0"/>
    <dynamics damping="0.0" friction="0.0"/>
  </joint>
  <link name="strut_rr_link">
    <visual>
      <origin rpy="-1.5707963267948966 -1.5707963267948966 0.0" xyz="-0.095 -0.03 -0.321"/>
      <geometry>
        <mesh filename="package://morpheus_description/urdf/01_robot_description/meshes/dae/strut.dae"/>
      </geometry>
    </visual>
    <collision>
      <origin rpy="-1.571 -1.5707999999991324 0.0" xyz="-0.0947906 -0.0295442 -0.320703"/>
      <geometry>
        <mesh filename="package://morpheus_description/urdf/01_robot_description/meshes/stl/strut.stl"/>
      </geometry>
    </collision>
    <inertial>
      <origin xyz="-0.0756316965 0.4736684486 -0.0149792473"/>
      <mass value="0.6"/>
      <inertia ixx="0.0120903014" ixy="0.0019549161" ixz="-1.01621e-05" iyy="0.000716067" iyz="5.92839e-05" izz="0.0122522986"/>
    </inertial>
  </link>
  <joint name="strut_rr_joint" type="fixed">
    <origin rpy="-3.1415899999999253 0.0 -1.5707999999991324" xyz="-0.0295442 0.00520945 -0.0899929"/>
    <parent link="shaft_right_link"/>
    <child link="strut_rr_link"/>
  </joint>
  <link name="steering_rr_link">
    <visual>
      <origin rpy="1.5707963267948966 0.0012042771838760874 0.0" xyz="-0.308 0.536 0.017"/>
      <geometry>
        <mesh filename="package://morpheus_description/urdf/01_robot_description/meshes/dae/steering.dae"/>
      </geometry>
    </visual>
    <collision>
      <origin rpy="1.571 0.0012006700002099185 0.0" xyz="-0.308035 0.536061 0.0167576"/>
      <geometry>
        <mesh filename="package://morpheus_description/urdf/01_robot_description/meshes/stl/steering.stl"/>
      </geometry>
    </collision>
    <inertial>
      <origin xyz="0.0008678457 0.0453345829 -0.1283715226"/>
      <mass value="1.6"/>
      <inertia ixx="0.0052284237" ixy="1.7963e-06" ixz="1.34245e-05" iyy="0.0053013768" iyz="0.0005026464" izz="0.0014739211"/>
    </inertial>
  </link>
  <joint name="steering_rr_joint" type="revolute">
    <origin rpy="1.5695899999993215 3.107946953589153 1.5708399999994722" xyz="-0.111216 0.504597 -0.0155261"/>
    <parent link="strut_rr_link"/>
    <child link="steering_rr_link"/>
    <axis xyz="0.0 0.0 1.0"/>
    <limit effort="10.0" lower="-3.141592653589793" upper="3.141592653589793" velocity="10.0"/>
    <dynamics damping="0.7" friction="0.0"/>
  </joint>
  <link name="wheel_rr_link">
    <visual>
      <origin rpy="0.0 0.0 0.0" xyz="0.0 0.0 -0.04"/>
      <geometry>
        <mesh filename="package://morpheus_description/urdf/01_robot_description/meshes/dae/wheel.dae"/>
      </geometry>
    </visual>
    <collision>
      <origin rpy="0.0 0.0 0.0" xyz="0.0 0.0 -0.04"/>
      <geometry>
        <mesh filename="package://morpheus_description/urdf/01_robot_description/meshes/stl/wheel.stl"/>
      </geometry>
    </collision>
    <inertial>
      <origin xyz="0.0001576409 -0.0006915734 -0.0400513418"/>
      <mass value="1.4"/>
      <inertia ixx="0.0063063969" ixy="6.7586e-06" ixz="2.6546e-06" iyy="0.0062998989" iyz="-2.919e-06" izz="0.0111226164"/>
    </inertial>
  </link>
  <joint name="wheel_rr_joint" type="continuous">
    <origin rpy="-1.5707999999991324 0.004421350000869758 -0.026179900000444293" xyz="0.000859913 0.0328387 -0.152"/>
    <parent link="steering_rr_link"/>
    <child link="wheel_rr_link"/>
    <axis xyz="0.0 0.0 1.0"/>
    <limit effort="10.0" lower="0.0" upper="0.0" velocity="10.0"/>
    <dynamics damping="0.0" friction="0.0"/>
  </joint>
  <link name="arm_base_link">
    <visual>
      <origin rpy="-1.5707963267948966 0.0 0.0" xyz="0.0 -0.001 0.188"/>
      <geometry>
        <mesh filename="package://morpheus_description/urdf/01_robot_description/meshes/stl/arm_base.stl"/>
      </geometry>
    </visual>
    <collision>
      <origin rpy="-1.571 0.0 0.0" xyz="0.0 -0.00128427 0.1875"/>
      <geometry>
        <mesh filename="package://morpheus_description/urdf/01_robot_description/meshes/stl/arm_base.stl"/>
      </geometry>
    </collision>
    <inertial>
      <origin xyz="0.002265802 0.0388509186 -0.1131686562"/>
      <mass value="1.8"/>
      <inertia ixx="0.0162321151" ixy="0.0002721762" ixz="-0.0002677049" iyy="0.0113995852" iyz="0.0047454194" izz="0.0077692693"/>
    </inertial>
  </link>
  <joint name="arm_base_joint" type="revolute">
    <origin rpy="3.1415899999999253 0.0 1.5707999999991324" xyz="0.0 0.0 0.0"/>
    <parent link="chassis_link"/>
    <child link="arm_base_link"/>
    <axis xyz="0.0 0.0 1.0"/>
    <limit effort="10000000.0" lower="-1.5699999999993148" upper="1.5699999999993148" velocity="0.5"/>
    <dynamics damping="0.7" friction="0.0"/>
  </joint>
  <link name="shoulder_link">
    <visual>
      <origin rpy="0.0 0.0 0.0" xyz="0.0 0.0 0.116"/>
      <geometry>
        <mesh filename="package://morpheus_description/urdf/01_robot_description/meshes/stl/shoulder.stl"/>
      </geometry>
      <material name="">
        <color rgba="0.9137254901960784 0.9137254901960784 0.9137254901960784 1.0"/>
      </material>
    </visual>
    <collision>
      <origin rpy="0.0 0.0 0.0" xyz="0.0 0.0 0.116"/>
      <geometry>
        <mesh filename="package://morpheus_description/urdf/01_robot_description/meshes/stl/shoulder.stl"/>
      </geometry>
    </collision>
    <inertial>
      <origin xyz="-0.1133303587 -0.2007144336 0.0548130181"/>
      <mass value="1.02"/>
      <inertia ixx="0.0209879592" ixy="-0.010495222" ixz="-5e-10" iyy="0.0083347477" iyz="-9e-10" izz="0.0264722807"/>
    </inertial>
  </link>
  <joint name="shoulder_joint" type="revolute">
    <origin rpy="1.5707999999991324 0.0 -1.5147899999996166" xyz="0.0441836 0.103854 -0.2255"/>
    <parent link="arm_base_link"/>
    <child link="shoulder_link"/>
    <axis xyz="0.0 0.0 1.0"/>
    <limit effort="100.0" lower="-1.5699999999993148" upper="1.5699999999993148" velocity="0.5"/>
    <dynamics damping="0.7" friction="0.0"/>
  </joint>
  <link name="elbow_link">
    <visual>
      <origin rpy="0.0 -1.5147887110983984 0.0" xyz="0.249 -0.096 -0.168"/>
      <geometry>
        <mesh filename="package://morpheus_description/urdf/01_robot_description/meshes/dae/elbow.dae"/>
      </geometry>
    </visual>
    <collision>
      <origin rpy="0.0 -1.5147899999996166 0.0" xyz="0.248798 -0.0958362 -0.167947"/>
      <geometry>
        <mesh filename="package://morpheus_description/urdf/01_robot_description/meshes/stl/elbow.stl"/>
      </geometry>
    </collision>
    <inertial>
      <origin xyz="-0.0050238328 -0.0036067228 -0.05513227"/>
      <mass value="0.6"/>
      <inertia ixx="0.0052896889" ixy="-0.0067539224" ixz="-1.75e-08" iyy="0.0107921785" iyz="-1.25e-08" izz="0.0153491622"/>
    </inertial>
  </link>
  <joint name="elbow_joint" type="revolute">
    <origin rpy="3.1415899999999253 0.0 0.0" xyz="-0.226229 -0.400525 0.0"/>
    <parent link="shoulder_link"/>
    <child link="elbow_link"/>
    <axis xyz="0.0 0.0 1.0"/>
    <limit effort="100.0" lower="-1.5699999999993148" upper="1.5699999999993148" velocity="0.5"/>
    <dynamics damping="0.7" friction="0.0"/>
  </joint>
  <link name="wrist_1_link">
    <visual>
      <origin rpy="2.2919663737189535 0.004328416544945937 0.0" xyz="-0.072 1.339 0.005"/>
      <geometry>
        <mesh filename="package://morpheus_description/urdf/01_robot_description/meshes/dae/wrist_1.dae"/>
      </geometry>
    </visual>
    <collision>
      <origin rpy="2.292 0.0043248200008068885 0.0" xyz="-0.0722471 1.33888 0.00527916"/>
      <geometry>
        <mesh filename="package://morpheus_description/urdf/01_robot_description/meshes/stl/wrist_1.stl"/>
      </geometry>
    </collision>
    <inertial>
      <origin xyz="-0.0132893283 -0.0069919863 -0.0370681388"/>
      <mass value="0.08"/>
      <inertia ixx="3.79839e-05" ixy="9.4919e-06" ixz="-2.2042e-06" iyy="8.48249e-05" iyz="-3.16e-07" izz="9.01278e-05"/>
    </inertial>
  </link>
  <joint name="wrist_1_joint" type="revolute">
    <origin rpy="-1.5707999999991324 -1.5395200000003404 -0.978813999999683" xyz="-0.485454 -0.326434 -0.05"/>
    <parent link="elbow_link"/>
    <child link="wrist_1_link"/>
    <axis xyz="0.0 0.0 1.0"/>
    <limit effort="10.0" lower="-1.5699999999993148" upper="1.5699999999993148" velocity="0.5"/>
    <dynamics damping="0.7" friction="0.0"/>
  </joint>
  <link name="wrist_2_link">
    <visual>
      <origin rpy="-2.3987456173559663 1.3738533739998564 0.0" xyz="0.89 -0.214 -0.131"/>
      <geometry>
        <mesh filename="package://morpheus_description/urdf/01_robot_description/meshes/dae/wrist_2.dae"/>
      </geometry>
    </visual>
    <collision>
      <origin rpy="-2.399 1.3738499999991596 0.0" xyz="0.889902 -0.21445 -0.131159"/>
      <geometry>
        <mesh filename="package://morpheus_description/urdf/01_robot_description/meshes/stl/wrist_2.stl"/>
      </geometry>
    </collision>
    <inertial>
      <origin xyz="0.0059561146 0.049056893 0.0006383682"/>
      <mass value="0.08"/>
      <inertia ixx="4.96495e-05" ixy="9.0534e-06" ixz="-1.205e-07" iyy="6.44478e-05" iyz="-9.71e-08" izz="8.47334e-05"/>
    </inertial>
  </link>
  <joint name="wrist_2_joint" type="revolute">
    <origin rpy="-1.5707999999991324 0.022103900000362674 1.3738999999995847" xyz="-0.00138273 -0.00999864 -0.037604"/>
    <parent link="wrist_1_link"/>
    <child link="wrist_2_link"/>
    <axis xyz="0.0 0.0 1.0"/>
    <limit effort="10.0" lower="-1.5699999999993148" upper="1.5699999999993148" velocity="0.5"/>
    <dynamics damping="0.7" friction="0.0"/>
  </joint>
  <link name="wrist_3_link">
    <visual>
      <origin rpy="-2.864975420441212 -0.17638297420654694 0.0" xyz="0.046 0.154 1.012"/>
      <geometry>
        <mesh filename="package://morpheus_description/urdf/01_robot_description/meshes/dae/wrist_3.dae"/>
      </geometry>
    </visual>
    <collision>
      <origin rpy="-2.865 -0.17638300000076795 0.0" xyz="0.0463147 0.153846 1.01185"/>
      <geometry>
        <mesh filename="package://morpheus_description/urdf/01_robot_description/meshes/stl/wrist_3.stl"/>
      </geometry>
    </collision>
    <inertial>
      <origin xyz="0.0010284481 0.1028040545 -0.0212436634"/>
      <mass value="0.05"/>
      <inertia ixx="0.0001637515" ixy="8.465e-07" ixz="4.77e-08" iyy="7.49074e-05" iyz="7.012e-07" izz="0.0001358161"/>
    </inertial>
  </link>
  <joint name="wrist_3_joint" type="revolute">
    <origin rpy="1.5707999999991324 1.5095100000001238 1.1123600000004843" xyz="0.0400622 0.0359864 0.0006"/>
    <parent link="wrist_2_link"/>
    <child link="wrist_3_link"/>
    <axis xyz="0.0 0.0 1.0"/>
    <limit effort="10.0" lower="-1.5699999999993148" upper="1.5699999999993148" velocity="0.5"/>
    <dynamics damping="0.7" friction="0.0"/>
  </joint>
  <link name="gripper_left_link">
    <visual>
      <origin rpy="-2.3887797873270786 1.3777105516467638 0.0" xyz="0.66 -0.212 0.595"/>
      <geometry>
        <mesh filename="package://morpheus_description/urdf/01_robot_description/meshes/dae/gripper_left.dae"/>
      </geometry>
    </visual>
    <collision>
      <origin rpy="-2.389 1.3777100000005473 0.0" xyz="0.659694 -0.211521 0.595012"/>
      <geometry>
        <mesh filename="package://morpheus_description/urdf/01_robot_description/meshes/stl/gripper_left.stl"/>
      </geometry>
    </collision>
    <inertial>
      <origin xyz="0.0323038354 0.050833515 0.005984972"/>
      <mass value="0.01"/>
      <inertia ixx="1.05006e-05" ixy="-6.5157e-06" ixz="-0.0" iyy="9.9021e-06" iyz="-0.0" izz="1.67378e-05"/>
    </inertial>
  </link>
  <joint name="gripper_left_joint" type="revolute">
    <origin rpy="-1.5803600000000912 -1.1025699999993164 1.491260000000364" xyz="0.004743 0.123063 -0.0638803"/>
    <parent link="wrist_3_link"/>
    <child link="gripper_left_link"/>
    <axis xyz="0.0 0.0 1.0"/>
    <limit effort="10.0" lower="-0.299999999999569" upper="0.299999999999569" velocity="0.5"/>
    <dynamics damping="0.7" friction="0.0"/>
  </joint>
  <link name="gripper_right_link">
    <visual>
      <origin rpy="-2.3887797873270786 1.3777105516467638 0.0" xyz="0.832 -0.256 0.34"/>
      <geometry>
        <mesh filename="package://morpheus_description/urdf/01_robot_description/meshes/dae/gripper_right.dae"/>
      </geometry>
    </visual>
    <collision>
      <origin rpy="-2.389 1.3777100000005473 0.0" xyz="0.832297 -0.255954 0.339569"/>
      <geometry>
        <mesh filename="package://morpheus_description/urdf/01_robot_description/meshes/stl/gripper_right.stl"/>
      </geometry>
    </collision>
    <inertial>
      <origin xyz="0.022069611 0.0561365687 0.0065971916"/>
      <mass value="0.01"/>
      <inertia ixx="0.0001633315" ixy="-2.22386e-05" ixz="-5.63e-08" iyy="4.06958e-05" iyz="-1.671e-07" izz="0.0001673785"/>
    </inertial>
  </link>
  <joint name="gripper_right_joint" type="revolute">
    <origin rpy="-1.5803600000000912 -1.1025699999993164 1.491260000000364" xyz="0.00437986 0.123095 0.0205453"/>
    <parent link="wrist_3_link"/>
    <child link="gripper_right_link"/>
    <axis xyz="0.0 0.0 1.0"/>
    <limit effort="10.0" lower="-0.299999999999569" upper="0.299999999999569" velocity="0.5"/>
    <dynamics damping="0.7" friction="0.0"/>
    <mimic joint="gripper_left_joint" multiplier="-1.0" offset="0.0"/>
  </joint>
  <link name="drill_link">
    <visual>
      <origin rpy="0.0 0.0 0.0" xyz="0.0 0.0 0.0"/>
      <geometry>
        <mesh filename="package://morpheus_description/urdf/01_robot_description/meshes/stl/drill.stl"/>
      </geometry>
    </visual>
    <collision>
      <origin rpy="0.0 0.0 0.0" xyz="0.0 0.0 0.0"/>
      <geometry>
        <mesh filename="package://morpheus_description/urdf/01_robot_description/meshes/stl/drill.stl"/>
      </geometry>
    </collision>
    <inertial>
      <origin xyz="0.0110555086 -0.0108942012 -0.8822038577"/>
      <mass value="0.15"/>
      <inertia ixx="0.0040102345" ixy="2.5998e-05" ixz="0.0001236482" iyy="0.0038324694" iyz="-8.29973e-05" izz="0.000326035"/>
    </inertial>
  </link>
  <joint name="drill_joint" type="fixed">
    <origin rpy="3.141592653589793 0.0 -1.5707963267948966" xyz="-0.375 0.145 -0.765"/>
    <parent link="chassis_link"/>
    <child link="drill_link"/>
  </joint>
  <link name="sample_box_1_link">
    <visual>
      <origin rpy="0.0 0.0 1.5707963267948966" xyz="0.0 0.0 0.01"/>
      <geometry>
        <mesh filename="package://morpheus_description/urdf/01_robot_description/meshes/stl/sample_box.stl"/>
      </geometry>
      <material name="">
        <color rgba="0.4666666666666667 0.4627450980392157 0.4823529411764706 1.0"/>
      </material>
    </visual>
    <collision>
      <origin rpy="0.0 0.0 1.5707963267948966" xyz="0.0 0.0 0.0"/>
      <geometry>
        <mesh filename="package://morpheus_description/urdf/01_robot_description/meshes/stl/sample_box.stl"/>
      </geometry>
    </collision>
    <inertial>
      <origin xyz="0.0 0.0 0.0047360703"/>
      <mass value="0.2"/>
      <inertia ixx="0.0007266667" ixy="0.0" ixz="0.0" iyy="0.0002266667" iyz="0.0" izz="0.0008333334"/>
    </inertial>
  </link>
  <joint name="sample_box_1_joint" type="fixed">
    <origin rpy="0.0 0.0 0.0" xyz="0.25 0.0 0.01"/>
    <parent link="chassis_link"/>
    <child link="sample_box_1_link"/>
  </joint>
  <link name="sample_box_2_link">
    <visual>
      <origin rpy="0.0 0.0 1.5707963267948966" xyz="0.0 0.0 0.01"/>
      <geometry>
        <mesh filename="package://morpheus_description/urdf/01_robot_description/meshes/stl/sample_box.stl"/>
      </geometry>
      <material name="">
        <color rgba="0.4666666666666667 0.4627450980392157 0.4823529411764706 1.0"/>
      </material>
    </visual>
    <collision>
      <origin rpy="0.0 0.0 1.5707963267948966" xyz="0.0 0.0 0.0"/>
      <geometry>
        <mesh filename="package://morpheus_description/urdf/01_robot_description/meshes/stl/sample_box.stl"/>
      </geometry>
    </collision>
    <inertial>
      <origin xyz="0.0 0.0 0.0047360703"/>
      <mass value="0.2"/>
      <inertia ixx="0.0007266667" ixy="0.0" ixz="0.0" iyy="0.0002266667" iyz="0.0" izz="0.0008333334"/>
    </inertial>
  </link>
  <joint name="sample_box_2_joint" type="fixed">
    <origin rpy="0.0 0.0 0.0" xyz="-0.25 0.0 0.01"/>
    <parent link="chassis_link"/>
    <child link="sample_box_2_link"/>
  </joint>
  <link name="zed_mini_link">
    <visual>
      <origin rpy="0.0 1.5707963267948966 0.0" xyz="0.0 0.0 0.0"/>
      <geometry>
        <box size="0.02 0.02 0.01"/>
      </geometry>
      <material name="">
        <color rgba="0.0 0.0 0.0 1.0"/>
      </material>
    </visual>
    <collision>
      <origin rpy="0.0 0.0 0.0" xyz="0.0 0.0 0.0"/>
      <geometry>
        <box size="0.02 0.02 0.01"/>
      </geometry>
    </collision>
    <inertial>
      <origin xyz="0.0 0.0 0.0"/>
      <mass value="0.08"/>
      <inertia ixx="5.3333e-06" ixy="0.0" ixz="0.0" iyy="3.3333e-06" iyz="0.0" izz="3.3333e-06"/>
    </inertial>
  </link>
  <joint name="zed_mini_joint" type="fixed">
    <origin rpy="0.0 0.0 0.0" xyz="0.1 0.1 0.1"/>
    <parent link="wrist_2_link"/>
    <child link="zed_mini_link"/>
  </joint>
  <link name="os0_lidar_link">
    <visual>
      <origin rpy="0.0 0.0 0.0" xyz="0.0 0.0 0.0"/>
      <geometry>
        <mesh filename="package://morpheus_description/urdf/01_robot_description/meshes/dae/os0_lidar.dae"/>
      </geometry>
    </visual>
    <collision>
      <origin rpy="0.0 0.0 0.0" xyz="0.0 0.0 0.0"/>
      <geometry>
        <box size="0.5 0.5 0.5"/>
      </geometry>
    </collision>
    <inertial>
      <origin xyz="-0.0178636494 -0.0004425342 0.0269007094"/>
      <mass value="0.4"/>
      <inertia ixx="0.0003556192" ixy="-3.2e-09" ixz="-3.3913e-06" iyy="0.0003538593" iyz="-8.6e-09" izz="0.0003519074"/>
    </inertial>
  </link>
  <joint name="os0_lidar_joint" type="fixed">
    <origin rpy="0.0 0.0 0.0" xyz="0.0 0.0 1.0"/>
    <parent link="chassis_link"/>
    <child link="os0_lidar_link"/>
  </joint>
  <link name="zed_2i_link">
    <visual>
      <origin rpy="0.0 0.0 0.0" xyz="0.0 0.0 0.0"/>
      <geometry>
        <box size="0.05 0.1 0.05"/>
      </geometry>
      <material name="">
        <color rgba="0.1803921568627451 0.7607843137254902 0.49411764705882355 1.0"/>
      </material>
    </visual>
    <collision>
      <origin rpy="0.0 0.0 0.0" xyz="0.0 0.0 0.0"/>
      <geometry>
        <box size="0.5 0.5 0.5"/>
      </geometry>
    </collision>
    <inertial>
      <origin xyz="0.0 0.0 0.0"/>
      <mass value="1.0"/>
      <inertia ixx="1.0" ixy="0.0" ixz="0.0" iyy="1.0" iyz="0.0" izz="1.0"/>
    </inertial>
  </link>
  <joint name="zed_2i_joint" type="fixed">
    <origin rpy="0.0 0.0 0.0" xyz="0.35 0.0 0.0"/>
    <parent link="chassis_link"/>
    <child link="zed_2i_link"/>
  </joint>
</robot>
